<?xml version='1.0'?>

<robot name="my_robot" xmlns:xacro="http://www.ros.org/wiki/xacro">
  
  <xacro:include filename="$(find my_robot)/urdf/my_robot.gazebo" />

  <link name="robot_footprint"></link>

  <joint name="robot_footprint_joint" type="fixed">
    <origin xyz="0 0 0" rpy="0 0 0" />
    <parent link="robot_footprint"/>
    <child link="chassis" />
  </joint>

  <link name='chassis'>
    <pose>0 0 0.0525 0 0 0</pose>

    <inertial>
      <mass value="10.0"/>
      <origin xyz="0 0 0" rpy=" 0 0 0"/>
      <inertia
          ixx="0.1" ixy="0" ixz="0"
          iyy="0.1" iyz="0"
          izz="0.1"
      />
    </inertial>

    <collision name='collision'>
      <origin xyz="0 0 0" rpy=" 0 0 0"/> 
      <geometry>
        <box size=".5 .2 .01"/>
      </geometry>
    </collision>

    <visual name='chassis_visual'>
      <origin xyz="0 0 0" rpy=" 0 0 0"/>
      <geometry>
        <box size=".5 .2 .01"/>
      </geometry>
    </visual>

    <!-- casters -->  
    <xacro:property name="caster_x" value="0.1" />
  
    <collision name='back_caster_collision'>
      <origin xyz="${caster_x} -0.0 -0.03" rpy=" 0 0 0"/>
      <geometry>
        <sphere radius="0.0199"/>
      </geometry>
    </collision>

    <visual name='back_caster_visual'>
      <origin xyz="${caster_x} -0.0 -0.03" rpy=" 0 0 0"/>
      <geometry>
        <sphere radius="0.02"/>
      </geometry>
    </visual>
  
    <collision name='front_caster_collision'>
      <origin xyz="-${caster_x} -0.0 -0.03" rpy=" 0 0 0"/>
      <geometry>
        <sphere radius="0.0199"/>
      </geometry>
    </collision>

    <visual name='front_caster_visual'>
      <origin xyz="-${caster_x} -0.0 -0.03" rpy=" 0 0 0"/>
      <geometry>
        <sphere radius="0.02"/>
      </geometry>
    </visual>
    

    <!-- Add the Cybertruck -->
    <visual>
      <origin xyz="0.02 0 -0.05" rpy="0 0 0" />
      <geometry>
        <mesh filename="package://my_robot/meshes/cybertruck.stl"/>
      </geometry>
    </visual>
    
    <collision>
      <origin xyz="0 0 0" rpy="0 0 0" />
      <geometry>
        <box size=".5 .2 .01"/>
      </geometry>
    </collision>
 
  </link>

  <!-- Add wheels -->
  <xacro:property name="wheel_radius" value="0.04" />
  <xacro:property name="wheel_mass" value="10" />
  <xacro:property name="wheel_inertia" value="0.2" />
  
  <link name='left_wheel'>
    <visual>
      <origin xyz="0 0 0" rpy="0 1.5707 1.5707" />
      <geometry>
        <cylinder radius="${wheel_radius}" length="0.035"/>
      </geometry>
    </visual>
    
    <collision>
      <origin xyz="0 0 0" rpy="0 1.5707 1.5707" />
      <geometry>
        <cylinder radius="${wheel_radius}" length="0.035"/>
      </geometry>
    </collision>
    
    <inertial>
      <mass value="${wheel_mass}"/>
      <origin xyz="0.0 0 0" rpy=" 0 0 0"/>
      <inertia
        ixx="${wheel_inertia}" ixy="0" ixz="0"
        iyy="${wheel_inertia}" iyz="0"
        izz="${wheel_inertia}"
      />
    </inertial>
  </link>

  <joint type="continuous" name="left_wheel_hinge">
    <origin xyz="0 0.083 -0.01" rpy="0 0 0"/>
    <child link="left_wheel"/>
    <parent link="chassis"/>
    <axis xyz="0 1 0" rpy="0 0 0"/>
    <limit effort="10000" velocity="1000"/>
    <dynamics damping="1.0" friction="1.0"/>
  </joint>
  

  <link name='right_wheel'>
    <visual>
      <origin xyz="0 0 0" rpy="0 1.5707 1.5707" />
      <geometry>
        <cylinder radius="${wheel_radius}" length="0.035"/>
      </geometry>
    </visual>
    
    <collision>
      <origin xyz="0 0 0" rpy="0 1.5707 1.5707" />
      <geometry>
        <cylinder radius="${wheel_radius}" length="0.035"/>
      </geometry>
    </collision>
    
    <inertial>
      <mass value="${wheel_mass}"/>
      <origin xyz="0 0 0" rpy=" 0 0 0"/>
      <inertia
        ixx="${wheel_inertia}" ixy="0" ixz="0"
        iyy="${wheel_inertia}" iyz="0"
        izz="${wheel_inertia}"
      />
    </inertial>
  </link>

  <joint type="continuous" name="right_wheel_hinge">
    <origin xyz="0 -0.083 -0.01" rpy="0 0 0"/>
    <child link="right_wheel"/>
    <parent link="chassis"/>
    <axis xyz="0 1 0" rpy="0 0 0"/>
    <limit effort="10000" velocity="1000"/>
    <dynamics damping="1.0" friction="1.0"/>
  </joint>


  <!-- Add front wheels -->
  <!--
  <link name='front_left_wheel'>
    <visual>
      <origin xyz="0 0 0" rpy="0 1.5707 1.5707" />
      <geometry>
        <cylinder radius="0.04" length="0.035"/>
      </geometry>
    </visual>
    
    <collision>
      <origin xyz="0 0 0" rpy="0 1.5707 1.5707" />
      <geometry>
        <cylinder radius="0.04" length="0.035"/>
      </geometry>
    </collision>
    
    <inertial>
      <mass value="5"/>
      <origin xyz="0.0 0 0" rpy=" 0 0 0"/>
      <inertia
        ixx="0.1" ixy="0" ixz="0"
        iyy="0.1" iyz="0"
        izz="0.1"
      />
    </inertial>
  </link>

  <joint type="continuous" name="front_left_wheel_hinge">
    <origin xyz=".2 0.083 0" rpy="0 0 0"/>
    <child link="front_left_wheel"/>
    <parent link="chassis"/>
    <axis xyz="0 1 0" rpy="0 0 0"/>
    <limit effort="10000" velocity="1000"/>
    <dynamics damping="1.0" friction="1.0"/>
  </joint>
  

  <link name='front_right_wheel'>
    <visual>
      <origin xyz="0 0 0" rpy="0 1.5707 1.5707" />
      <geometry>
        <cylinder radius="0.04" length="0.03"/>
      </geometry>
    </visual>
    
    <collision>
      <origin xyz="0 0 0" rpy="0 1.5707 1.5707" />
      <geometry>
        <cylinder radius="0.04" length="0.03"/>
      </geometry>
    </collision>
    
    <inertial>
      <mass value="5"/>
      <origin xyz="0 0 0" rpy=" 0 0 0"/>
      <inertia
        ixx="0.1" ixy="0" ixz="0"
        iyy="0.1" iyz="0"
        izz="0.1"
      />
    </inertial>
  </link>

  <joint type="continuous" name="front_right_wheel_hinge">
    <origin xyz=".2 -0.083 0" rpy="0 0 0"/>
    <child link="front_right_wheel"/>
    <parent link="chassis"/>
    <axis xyz="0 1 0" rpy="0 0 0"/>
    <limit effort="10000" velocity="1000"/>
    <dynamics damping="1.0" friction="1.0"/>
  </joint>
-->

  <!-- Add camera -->
  <link name="camera_link">
    <visual>
      <origin xyz="0 0 0" rpy="0 0 0" />
      <geometry>
        <box size=".05 .05 .05"/>
      </geometry>
    </visual>
    
    <collision>
      <origin xyz="0 0 0" rpy="0 0 0" />
      <geometry>
        <box size=".05 .05 .05"/>
      </geometry>
    </collision>
    
    <inertial>
      <mass value=".1"/>
      <origin xyz="0 0 0" rpy=" 0 0 0"/>
      <inertia
        ixx="1e-6" ixy="0" ixz="0"
        iyy="1e-6" iyz="0"
        izz="1e-6"
      />
      <box_inertia m=".1" x=".05" y=".05" z=".05"/>
    </inertial>
  </link>
  
  <joint type="fixed" name="camera_joint">
    <origin xyz=".25 0 .03" rpy="0 0 0"/>
    <child link="camera_link"/>
    <parent link="chassis"/>
  </joint>
  
  
  <!-- Add Lidar -->
  <link name="hokuyo">
    <visual>
      <origin xyz="0 0 0" rpy="0 0 0" />
      <geometry>
        <mesh filename="package://my_robot/meshes/hokuyo.dae"/>
      </geometry>
    </visual>
    
    <collision>
      <origin xyz="0 0 0" rpy="0 0 0" />
      <geometry>
        <box size=".1 .1 .1"/>
      </geometry>
    </collision>
    
    <inertial>
      <mass value="1e-5"/>
      <origin xyz="0 0 0" rpy=" 0 0 0"/>
      <inertia
        ixx="1e-6" ixy="0" ixz="0"
        iyy="1e-6" iyz="0"
        izz="1e-6"
      />
    </inertial>
  </link>
  
  <joint type="fixed" name="hokuyo_joint">
    <origin xyz=".0 0 .125" rpy="0 0 0"/>
    <child link="hokuyo"/>
    <parent link="chassis"/>
    <axis xyz="0 1 0" rpy="0 0 0"/>
  </joint>
  
  <!-- Add colors -->
  <gazebo reference="left_wheel">
    <material>Gazebo/Grey</material>
  </gazebo>
  <gazebo reference="right_wheel">
    <material>Gazebo/Grey</material>
  </gazebo>
  <gazebo reference="chassis">
    <material>Gazebo/Gray</material>
  </gazebo>
  <gazebo reference="camera">
    <material>Gazebo/Black</material>
  </gazebo>
  
  <!-- optical camera -->
  <joint name="camera_optical_joint" type="fixed">
    <origin xyz="0 0 0" rpy="-1.5707 0 -1.5707"/>
    <parent link="camera_link"/>
    <child link="camera_link_optical"/>
  </joint>

  <link name="camera_link_optical">
  </link>
  
</robot>

